[2025-02-21T09:20:56.691+0000] {taskinstance.py:1956} INFO - Dependencies all met for dep_context=non-requeueable deps ti=<TaskInstance: optum_file_dag.transform_task scheduled__2025-01-10T00:00:00+00:00 [queued]>
[2025-02-21T09:20:56.757+0000] {taskinstance.py:1956} INFO - Dependencies all met for dep_context=requeueable deps ti=<TaskInstance: optum_file_dag.transform_task scheduled__2025-01-10T00:00:00+00:00 [queued]>
[2025-02-21T09:20:56.758+0000] {taskinstance.py:2170} INFO - Starting attempt 1 of 2
[2025-02-21T09:20:56.847+0000] {taskinstance.py:2191} INFO - Executing <Task(PythonOperator): transform_task> on 2025-01-10 00:00:00+00:00
[2025-02-21T09:20:56.904+0000] {standard_task_runner.py:60} INFO - Started process 4799 to run task
[2025-02-21T09:20:56.924+0000] {standard_task_runner.py:87} INFO - Running: ['***', 'tasks', 'run', 'optum_file_dag', 'transform_task', 'scheduled__2025-01-10T00:00:00+00:00', '--job-id', '791', '--raw', '--subdir', 'DAGS_FOLDER/optum_file_dag.py', '--cfg-path', '/tmp/tmp35f6pzzo']
[2025-02-21T09:20:56.935+0000] {standard_task_runner.py:88} INFO - Job 791: Subtask transform_task
[2025-02-21T09:20:57.355+0000] {task_command.py:423} INFO - Running <TaskInstance: optum_file_dag.transform_task scheduled__2025-01-10T00:00:00+00:00 [running]> on host 491940227afd
[2025-02-21T09:20:57.803+0000] {taskinstance.py:2480} INFO - Exporting env vars: AIRFLOW_CTX_DAG_OWNER='***' AIRFLOW_CTX_DAG_ID='optum_file_dag' AIRFLOW_CTX_TASK_ID='transform_task' AIRFLOW_CTX_EXECUTION_DATE='2025-01-10T00:00:00+00:00' AIRFLOW_CTX_TRY_NUMBER='1' AIRFLOW_CTX_DAG_RUN_ID='scheduled__2025-01-10T00:00:00+00:00'
[2025-02-21T09:20:57.811+0000] {taskinstance.py:2698} ERROR - Task failed with exception
Traceback (most recent call last):
  File "/home/airflow/.local/lib/python3.8/site-packages/airflow/models/taskinstance.py", line 433, in _execute_task
    result = execute_callable(context=context, **execute_callable_kwargs)
  File "/home/airflow/.local/lib/python3.8/site-packages/airflow/operators/python.py", line 199, in execute
    return_value = self.execute_callable()
  File "/home/airflow/.local/lib/python3.8/site-packages/airflow/operators/python.py", line 216, in execute_callable
    return self.python_callable(*self.op_args, **self.op_kwargs)
  File "/opt/airflow/dags/optum_file_dag.py", line 28, in transform
    fo.write(line.split()[0] + '\n')
IndexError: list index out of range
[2025-02-21T09:20:57.910+0000] {taskinstance.py:1138} INFO - Marking task as UP_FOR_RETRY. dag_id=optum_file_dag, task_id=transform_task, execution_date=20250110T000000, start_date=20250221T092056, end_date=20250221T092057
[2025-02-21T09:20:57.952+0000] {standard_task_runner.py:107} ERROR - Failed to execute job 791 for task transform_task (list index out of range; 4799)
[2025-02-21T09:20:58.117+0000] {local_task_job_runner.py:234} INFO - Task exited with return code 1
[2025-02-21T09:20:58.226+0000] {taskinstance.py:3280} INFO - 0 downstream tasks scheduled from follow-on schedule check
