[2025-02-21T09:23:56.394+0000] {taskinstance.py:1956} INFO - Dependencies all met for dep_context=non-requeueable deps ti=<TaskInstance: optum_file_dag.transform_task scheduled__2025-01-24T00:00:00+00:00 [queued]>
[2025-02-21T09:23:56.445+0000] {taskinstance.py:1956} INFO - Dependencies all met for dep_context=requeueable deps ti=<TaskInstance: optum_file_dag.transform_task scheduled__2025-01-24T00:00:00+00:00 [queued]>
[2025-02-21T09:23:56.447+0000] {taskinstance.py:2170} INFO - Starting attempt 2 of 2
[2025-02-21T09:23:56.487+0000] {taskinstance.py:2191} INFO - Executing <Task(PythonOperator): transform_task> on 2025-01-24 00:00:00+00:00
[2025-02-21T09:23:56.567+0000] {standard_task_runner.py:60} INFO - Started process 5034 to run task
[2025-02-21T09:23:56.599+0000] {standard_task_runner.py:87} INFO - Running: ['***', 'tasks', 'run', 'optum_file_dag', 'transform_task', 'scheduled__2025-01-24T00:00:00+00:00', '--job-id', '856', '--raw', '--subdir', 'DAGS_FOLDER/optum_file_dag.py', '--cfg-path', '/tmp/tmp7iuy70__']
[2025-02-21T09:23:56.642+0000] {standard_task_runner.py:88} INFO - Job 856: Subtask transform_task
[2025-02-21T09:23:56.947+0000] {task_command.py:423} INFO - Running <TaskInstance: optum_file_dag.transform_task scheduled__2025-01-24T00:00:00+00:00 [running]> on host 491940227afd
[2025-02-21T09:23:57.277+0000] {taskinstance.py:2480} INFO - Exporting env vars: AIRFLOW_CTX_DAG_OWNER='***' AIRFLOW_CTX_DAG_ID='optum_file_dag' AIRFLOW_CTX_TASK_ID='transform_task' AIRFLOW_CTX_EXECUTION_DATE='2025-01-24T00:00:00+00:00' AIRFLOW_CTX_TRY_NUMBER='2' AIRFLOW_CTX_DAG_RUN_ID='scheduled__2025-01-24T00:00:00+00:00'
[2025-02-21T09:23:57.294+0000] {taskinstance.py:2698} ERROR - Task failed with exception
Traceback (most recent call last):
  File "/home/airflow/.local/lib/python3.8/site-packages/airflow/models/taskinstance.py", line 433, in _execute_task
    result = execute_callable(context=context, **execute_callable_kwargs)
  File "/home/airflow/.local/lib/python3.8/site-packages/airflow/operators/python.py", line 199, in execute
    return_value = self.execute_callable()
  File "/home/airflow/.local/lib/python3.8/site-packages/airflow/operators/python.py", line 216, in execute_callable
    return self.python_callable(*self.op_args, **self.op_kwargs)
  File "/opt/airflow/dags/optum_file_dag.py", line 28, in transform
    fo.write(line.split()[0] + '\n')
IndexError: list index out of range
[2025-02-21T09:23:57.361+0000] {taskinstance.py:1138} INFO - Marking task as FAILED. dag_id=optum_file_dag, task_id=transform_task, execution_date=20250124T000000, start_date=20250221T092356, end_date=20250221T092357
[2025-02-21T09:23:57.415+0000] {standard_task_runner.py:107} ERROR - Failed to execute job 856 for task transform_task (list index out of range; 5034)
[2025-02-21T09:23:57.498+0000] {local_task_job_runner.py:234} INFO - Task exited with return code 1
[2025-02-21T09:23:57.585+0000] {taskinstance.py:3280} INFO - 0 downstream tasks scheduled from follow-on schedule check
