[2025-02-21T07:42:57.189+0000] {processor.py:161} INFO - Started process (PID=9713) to work on /opt/airflow/dags/failed_ml_dag.py
[2025-02-21T07:42:57.193+0000] {processor.py:830} INFO - Processing file /opt/airflow/dags/failed_ml_dag.py for tasks to queue
[2025-02-21T07:42:57.199+0000] {logging_mixin.py:188} INFO - [2025-02-21T07:42:57.198+0000] {dagbag.py:538} INFO - Filling up the DagBag from /opt/airflow/dags/failed_ml_dag.py
[2025-02-21T07:42:58.369+0000] {logging_mixin.py:188} INFO - [2025-02-21T07:42:58.351+0000] {dagbag.py:348} ERROR - Failed to import: /opt/airflow/dags/failed_ml_dag.py
Traceback (most recent call last):
  File "/home/airflow/.local/lib/python3.8/site-packages/airflow/models/dagbag.py", line 344, in parse
    loader.exec_module(new_module)
  File "<frozen importlib._bootstrap_external>", line 843, in exec_module
  File "<frozen importlib._bootstrap>", line 219, in _call_with_frames_removed
  File "/opt/airflow/dags/failed_ml_dag.py", line 7, in <module>
    from sklearn.ensemble import RandomForestClassifier
ModuleNotFoundError: No module named 'sklearn'
[2025-02-21T07:42:58.375+0000] {processor.py:842} WARNING - No viable dags retrieved from /opt/airflow/dags/failed_ml_dag.py
[2025-02-21T07:42:58.428+0000] {processor.py:183} INFO - Processing /opt/airflow/dags/failed_ml_dag.py took 1.253 seconds
[2025-02-21T07:43:28.675+0000] {processor.py:161} INFO - Started process (PID=9776) to work on /opt/airflow/dags/failed_ml_dag.py
[2025-02-21T07:43:28.678+0000] {processor.py:830} INFO - Processing file /opt/airflow/dags/failed_ml_dag.py for tasks to queue
[2025-02-21T07:43:28.684+0000] {logging_mixin.py:188} INFO - [2025-02-21T07:43:28.683+0000] {dagbag.py:538} INFO - Filling up the DagBag from /opt/airflow/dags/failed_ml_dag.py
[2025-02-21T07:43:30.936+0000] {logging_mixin.py:188} INFO - [2025-02-21T07:43:30.918+0000] {dagbag.py:348} ERROR - Failed to import: /opt/airflow/dags/failed_ml_dag.py
Traceback (most recent call last):
  File "/home/airflow/.local/lib/python3.8/site-packages/airflow/models/dagbag.py", line 344, in parse
    loader.exec_module(new_module)
  File "<frozen importlib._bootstrap_external>", line 843, in exec_module
  File "<frozen importlib._bootstrap>", line 219, in _call_with_frames_removed
  File "/opt/airflow/dags/failed_ml_dag.py", line 7, in <module>
    from sklearn.ensemble import RandomForestClassifier
ModuleNotFoundError: No module named 'sklearn'
[2025-02-21T07:43:30.943+0000] {processor.py:842} WARNING - No viable dags retrieved from /opt/airflow/dags/failed_ml_dag.py
[2025-02-21T07:43:31.026+0000] {processor.py:183} INFO - Processing /opt/airflow/dags/failed_ml_dag.py took 2.356 seconds
[2025-02-21T07:44:01.614+0000] {processor.py:161} INFO - Started process (PID=9841) to work on /opt/airflow/dags/failed_ml_dag.py
[2025-02-21T07:44:01.624+0000] {processor.py:830} INFO - Processing file /opt/airflow/dags/failed_ml_dag.py for tasks to queue
[2025-02-21T07:44:01.633+0000] {logging_mixin.py:188} INFO - [2025-02-21T07:44:01.632+0000] {dagbag.py:538} INFO - Filling up the DagBag from /opt/airflow/dags/failed_ml_dag.py
[2025-02-21T07:44:02.910+0000] {logging_mixin.py:188} INFO - [2025-02-21T07:44:02.894+0000] {dagbag.py:348} ERROR - Failed to import: /opt/airflow/dags/failed_ml_dag.py
Traceback (most recent call last):
  File "/home/airflow/.local/lib/python3.8/site-packages/airflow/models/dagbag.py", line 344, in parse
    loader.exec_module(new_module)
  File "<frozen importlib._bootstrap_external>", line 843, in exec_module
  File "<frozen importlib._bootstrap>", line 219, in _call_with_frames_removed
  File "/opt/airflow/dags/failed_ml_dag.py", line 7, in <module>
    from sklearn.ensemble import RandomForestClassifier
ModuleNotFoundError: No module named 'sklearn'
[2025-02-21T07:44:02.916+0000] {processor.py:842} WARNING - No viable dags retrieved from /opt/airflow/dags/failed_ml_dag.py
[2025-02-21T07:44:02.977+0000] {processor.py:183} INFO - Processing /opt/airflow/dags/failed_ml_dag.py took 1.379 seconds
[2025-02-21T07:44:12.777+0000] {processor.py:161} INFO - Started process (PID=9871) to work on /opt/airflow/dags/failed_ml_dag.py
[2025-02-21T07:44:12.784+0000] {processor.py:830} INFO - Processing file /opt/airflow/dags/failed_ml_dag.py for tasks to queue
[2025-02-21T07:44:12.796+0000] {logging_mixin.py:188} INFO - [2025-02-21T07:44:12.792+0000] {dagbag.py:538} INFO - Filling up the DagBag from /opt/airflow/dags/failed_ml_dag.py
[2025-02-21T07:44:13.981+0000] {logging_mixin.py:188} INFO - [2025-02-21T07:44:13.966+0000] {dagbag.py:348} ERROR - Failed to import: /opt/airflow/dags/failed_ml_dag.py
Traceback (most recent call last):
  File "/home/airflow/.local/lib/python3.8/site-packages/airflow/models/dagbag.py", line 344, in parse
    loader.exec_module(new_module)
  File "<frozen importlib._bootstrap_external>", line 843, in exec_module
  File "<frozen importlib._bootstrap>", line 219, in _call_with_frames_removed
  File "/opt/airflow/dags/failed_ml_dag.py", line 7, in <module>
    from sklearn.ensemble import RandomForestClassifier
ModuleNotFoundError: No module named 'sklearn'
[2025-02-21T07:44:13.986+0000] {processor.py:842} WARNING - No viable dags retrieved from /opt/airflow/dags/failed_ml_dag.py
[2025-02-21T07:44:14.056+0000] {processor.py:183} INFO - Processing /opt/airflow/dags/failed_ml_dag.py took 1.291 seconds
[2025-02-21T07:44:44.422+0000] {processor.py:161} INFO - Started process (PID=9933) to work on /opt/airflow/dags/failed_ml_dag.py
[2025-02-21T07:44:44.426+0000] {processor.py:830} INFO - Processing file /opt/airflow/dags/failed_ml_dag.py for tasks to queue
[2025-02-21T07:44:44.432+0000] {logging_mixin.py:188} INFO - [2025-02-21T07:44:44.432+0000] {dagbag.py:538} INFO - Filling up the DagBag from /opt/airflow/dags/failed_ml_dag.py
[2025-02-21T07:44:45.679+0000] {logging_mixin.py:188} INFO - [2025-02-21T07:44:45.660+0000] {dagbag.py:348} ERROR - Failed to import: /opt/airflow/dags/failed_ml_dag.py
Traceback (most recent call last):
  File "/home/airflow/.local/lib/python3.8/site-packages/airflow/models/dagbag.py", line 344, in parse
    loader.exec_module(new_module)
  File "<frozen importlib._bootstrap_external>", line 843, in exec_module
  File "<frozen importlib._bootstrap>", line 219, in _call_with_frames_removed
  File "/opt/airflow/dags/failed_ml_dag.py", line 7, in <module>
    from sklearn.ensemble import RandomForestClassifier
ModuleNotFoundError: No module named 'sklearn'
[2025-02-21T07:44:45.684+0000] {processor.py:842} WARNING - No viable dags retrieved from /opt/airflow/dags/failed_ml_dag.py
[2025-02-21T07:44:45.732+0000] {processor.py:183} INFO - Processing /opt/airflow/dags/failed_ml_dag.py took 1.318 seconds
[2025-02-21T07:45:16.192+0000] {processor.py:161} INFO - Started process (PID=9997) to work on /opt/airflow/dags/failed_ml_dag.py
[2025-02-21T07:45:16.197+0000] {processor.py:830} INFO - Processing file /opt/airflow/dags/failed_ml_dag.py for tasks to queue
[2025-02-21T07:45:16.224+0000] {logging_mixin.py:188} INFO - [2025-02-21T07:45:16.222+0000] {dagbag.py:538} INFO - Filling up the DagBag from /opt/airflow/dags/failed_ml_dag.py
[2025-02-21T07:45:17.573+0000] {logging_mixin.py:188} INFO - [2025-02-21T07:45:17.535+0000] {dagbag.py:348} ERROR - Failed to import: /opt/airflow/dags/failed_ml_dag.py
Traceback (most recent call last):
  File "/home/airflow/.local/lib/python3.8/site-packages/airflow/models/dagbag.py", line 344, in parse
    loader.exec_module(new_module)
  File "<frozen importlib._bootstrap_external>", line 843, in exec_module
  File "<frozen importlib._bootstrap>", line 219, in _call_with_frames_removed
  File "/opt/airflow/dags/failed_ml_dag.py", line 7, in <module>
    from sklearn.ensemble import RandomForestClassifier
ModuleNotFoundError: No module named 'sklearn'
[2025-02-21T07:45:17.586+0000] {processor.py:842} WARNING - No viable dags retrieved from /opt/airflow/dags/failed_ml_dag.py
[2025-02-21T07:45:17.660+0000] {processor.py:183} INFO - Processing /opt/airflow/dags/failed_ml_dag.py took 1.479 seconds
[2025-02-21T07:45:48.113+0000] {processor.py:161} INFO - Started process (PID=10066) to work on /opt/airflow/dags/failed_ml_dag.py
[2025-02-21T07:45:48.116+0000] {processor.py:830} INFO - Processing file /opt/airflow/dags/failed_ml_dag.py for tasks to queue
[2025-02-21T07:45:48.121+0000] {logging_mixin.py:188} INFO - [2025-02-21T07:45:48.120+0000] {dagbag.py:538} INFO - Filling up the DagBag from /opt/airflow/dags/failed_ml_dag.py
[2025-02-21T07:45:49.224+0000] {logging_mixin.py:188} INFO - [2025-02-21T07:45:49.210+0000] {dagbag.py:348} ERROR - Failed to import: /opt/airflow/dags/failed_ml_dag.py
Traceback (most recent call last):
  File "/home/airflow/.local/lib/python3.8/site-packages/airflow/models/dagbag.py", line 344, in parse
    loader.exec_module(new_module)
  File "<frozen importlib._bootstrap_external>", line 843, in exec_module
  File "<frozen importlib._bootstrap>", line 219, in _call_with_frames_removed
  File "/opt/airflow/dags/failed_ml_dag.py", line 7, in <module>
    from sklearn.ensemble import RandomForestClassifier
ModuleNotFoundError: No module named 'sklearn'
[2025-02-21T07:45:49.229+0000] {processor.py:842} WARNING - No viable dags retrieved from /opt/airflow/dags/failed_ml_dag.py
[2025-02-21T07:45:49.275+0000] {processor.py:183} INFO - Processing /opt/airflow/dags/failed_ml_dag.py took 1.170 seconds
[2025-02-21T07:46:20.045+0000] {processor.py:161} INFO - Started process (PID=10131) to work on /opt/airflow/dags/failed_ml_dag.py
[2025-02-21T07:46:20.048+0000] {processor.py:830} INFO - Processing file /opt/airflow/dags/failed_ml_dag.py for tasks to queue
[2025-02-21T07:46:20.053+0000] {logging_mixin.py:188} INFO - [2025-02-21T07:46:20.052+0000] {dagbag.py:538} INFO - Filling up the DagBag from /opt/airflow/dags/failed_ml_dag.py
[2025-02-21T07:46:21.328+0000] {logging_mixin.py:188} INFO - [2025-02-21T07:46:21.307+0000] {dagbag.py:348} ERROR - Failed to import: /opt/airflow/dags/failed_ml_dag.py
Traceback (most recent call last):
  File "/home/airflow/.local/lib/python3.8/site-packages/airflow/models/dagbag.py", line 344, in parse
    loader.exec_module(new_module)
  File "<frozen importlib._bootstrap_external>", line 843, in exec_module
  File "<frozen importlib._bootstrap>", line 219, in _call_with_frames_removed
  File "/opt/airflow/dags/failed_ml_dag.py", line 7, in <module>
    from sklearn.ensemble import RandomForestClassifier
ModuleNotFoundError: No module named 'sklearn'
[2025-02-21T07:46:21.333+0000] {processor.py:842} WARNING - No viable dags retrieved from /opt/airflow/dags/failed_ml_dag.py
[2025-02-21T07:46:21.390+0000] {processor.py:183} INFO - Processing /opt/airflow/dags/failed_ml_dag.py took 1.355 seconds
[2025-02-21T07:46:51.962+0000] {processor.py:161} INFO - Started process (PID=10191) to work on /opt/airflow/dags/failed_ml_dag.py
[2025-02-21T07:46:51.966+0000] {processor.py:830} INFO - Processing file /opt/airflow/dags/failed_ml_dag.py for tasks to queue
[2025-02-21T07:46:51.976+0000] {logging_mixin.py:188} INFO - [2025-02-21T07:46:51.975+0000] {dagbag.py:538} INFO - Filling up the DagBag from /opt/airflow/dags/failed_ml_dag.py
[2025-02-21T07:46:53.600+0000] {logging_mixin.py:188} INFO - [2025-02-21T07:46:53.563+0000] {dagbag.py:348} ERROR - Failed to import: /opt/airflow/dags/failed_ml_dag.py
Traceback (most recent call last):
  File "/home/airflow/.local/lib/python3.8/site-packages/airflow/models/dagbag.py", line 344, in parse
    loader.exec_module(new_module)
  File "<frozen importlib._bootstrap_external>", line 843, in exec_module
  File "<frozen importlib._bootstrap>", line 219, in _call_with_frames_removed
  File "/opt/airflow/dags/failed_ml_dag.py", line 7, in <module>
    from sklearn.ensemble import RandomForestClassifier
ModuleNotFoundError: No module named 'sklearn'
[2025-02-21T07:46:53.610+0000] {processor.py:842} WARNING - No viable dags retrieved from /opt/airflow/dags/failed_ml_dag.py
[2025-02-21T07:46:53.668+0000] {processor.py:183} INFO - Processing /opt/airflow/dags/failed_ml_dag.py took 1.724 seconds
