[2025-02-21T09:20:56.591+0000] {taskinstance.py:1956} INFO - Dependencies all met for dep_context=non-requeueable deps ti=<TaskInstance: optum_file_dag.transform_task scheduled__2025-01-09T00:00:00+00:00 [queued]>
[2025-02-21T09:20:56.639+0000] {taskinstance.py:1956} INFO - Dependencies all met for dep_context=requeueable deps ti=<TaskInstance: optum_file_dag.transform_task scheduled__2025-01-09T00:00:00+00:00 [queued]>
[2025-02-21T09:20:56.646+0000] {taskinstance.py:2170} INFO - Starting attempt 1 of 2
[2025-02-21T09:20:56.729+0000] {taskinstance.py:2191} INFO - Executing <Task(PythonOperator): transform_task> on 2025-01-09 00:00:00+00:00
[2025-02-21T09:20:56.754+0000] {standard_task_runner.py:60} INFO - Started process 4797 to run task
[2025-02-21T09:20:56.779+0000] {standard_task_runner.py:87} INFO - Running: ['***', 'tasks', 'run', 'optum_file_dag', 'transform_task', 'scheduled__2025-01-09T00:00:00+00:00', '--job-id', '790', '--raw', '--subdir', 'DAGS_FOLDER/optum_file_dag.py', '--cfg-path', '/tmp/tmp0avijvsa']
[2025-02-21T09:20:56.813+0000] {standard_task_runner.py:88} INFO - Job 790: Subtask transform_task
[2025-02-21T09:20:57.096+0000] {task_command.py:423} INFO - Running <TaskInstance: optum_file_dag.transform_task scheduled__2025-01-09T00:00:00+00:00 [running]> on host 491940227afd
[2025-02-21T09:20:57.508+0000] {taskinstance.py:2480} INFO - Exporting env vars: AIRFLOW_CTX_DAG_OWNER='***' AIRFLOW_CTX_DAG_ID='optum_file_dag' AIRFLOW_CTX_TASK_ID='transform_task' AIRFLOW_CTX_EXECUTION_DATE='2025-01-09T00:00:00+00:00' AIRFLOW_CTX_TRY_NUMBER='1' AIRFLOW_CTX_DAG_RUN_ID='scheduled__2025-01-09T00:00:00+00:00'
[2025-02-21T09:20:57.520+0000] {taskinstance.py:2698} ERROR - Task failed with exception
Traceback (most recent call last):
  File "/home/airflow/.local/lib/python3.8/site-packages/airflow/models/taskinstance.py", line 433, in _execute_task
    result = execute_callable(context=context, **execute_callable_kwargs)
  File "/home/airflow/.local/lib/python3.8/site-packages/airflow/operators/python.py", line 199, in execute
    return_value = self.execute_callable()
  File "/home/airflow/.local/lib/python3.8/site-packages/airflow/operators/python.py", line 216, in execute_callable
    return self.python_callable(*self.op_args, **self.op_kwargs)
  File "/opt/airflow/dags/optum_file_dag.py", line 28, in transform
    fo.write(line.split()[0] + '\n')
IndexError: list index out of range
[2025-02-21T09:20:57.572+0000] {taskinstance.py:1138} INFO - Marking task as UP_FOR_RETRY. dag_id=optum_file_dag, task_id=transform_task, execution_date=20250109T000000, start_date=20250221T092056, end_date=20250221T092057
[2025-02-21T09:20:57.600+0000] {standard_task_runner.py:107} ERROR - Failed to execute job 790 for task transform_task (list index out of range; 4797)
[2025-02-21T09:20:57.692+0000] {local_task_job_runner.py:234} INFO - Task exited with return code 1
[2025-02-21T09:20:57.859+0000] {taskinstance.py:3280} INFO - 0 downstream tasks scheduled from follow-on schedule check
